<robot name="rover_replica">

<link name="rover_replica_base"/>

<link name="custom_base_link">
    <inertial>
        <origin xyz="0.0 0.0 0.0" rpy="0.0 0.0 0.0"/>
        <mass value="1.0"/>
        <inertia ixx="0.4" ixy="0.0" ixz="0.0"
                 iyy="0.4" iyz="0.0"
                 izz="0.2"/>
    </inertial>
    <visual name="">
        <origin xyz="0.0 0.0 0.0" rpy="0.0 0.0 0.0"/>
        <geometry>
            <box size="0.8 0.7 0.1"/>
        </geometry>
        <material name="">
            <color rgba="0.0 1.0 0.0 1.0"/>
            <texture filename=""/>
        </material>
    </visual>
    <collision>
        <origin xyz="0.0 0.0 0.0" rpy="0.0 0.0 0.0"/>
        <geometry>
            <box size="0.0 0.0 0.0"/>
        </geometry>
    </collision>
</link>

<joint name="custom_base_joint" type="fixed">
    <origin xyz="0.0 0.0 0.135" rpy="0.0 0.0 0.0"/>
    <parent link="rover_replica_base"/>
    <child link="custom_base_link"/>
    <axis xyz="0.0 0.0 0.0"/>
</joint>

<link name="rear_right_wheel_link">
    <inertial>
        <origin xyz="0.0 0.0 0.0" rpy="0.0 0.0 0.0"/>
        <mass value="1.0"/>
        <inertia ixx="0.4" ixy="0.0" ixz="0.0"
                 iyy="0.4" iyz="0.0"
                 izz="0.2"/>
    </inertial>
    <visual name="">
        <origin xyz="0.0 0.0 0.0" rpy="0.0 0.0 0.0"/>
        <geometry>
            <cylinder radius="0.15" length="0.1"/> 
        </geometry>
        <material name="red">
            <color rgba="1.0 0.0 0.0 1.0"/>
            <texture filename=""/>
        </material>
    </visual>
    <collision>
        <origin xyz="0.0 0.0 0.0" rpy="0.0 0.0 0.0"/>
        <geometry>
            <cylinder radius="0.15" length="0.1"/> 
        </geometry>
    </collision>
</link>

<joint name="rear_right_wheel_joint" type="continuous">
    <origin xyz="0.25 0.4 .0" rpy="1.57 0.0 0.0"/>
    <parent link="custom_base_link"/>
    <child link="rear_right_wheel_link"/>
    <axis xyz="0.0 0.0 1.0"/>
</joint>

<link name="rear_left_wheel_link">
    <inertial>
        <origin xyz="0.0 0.0 0.0" rpy="0.0 0.0 0.0"/>
        <mass value="1.0"/>
        <inertia ixx="0.4" ixy="0.0" ixz="0.0"
                 iyy="0.4" iyz="0.0"
                 izz="0.2"/>
    </inertial>
    <visual name="">
        <origin xyz="0.0 0.0 0.0" rpy="0.0 0.0 0.0"/>
        <geometry>
            <cylinder radius="0.15" length="0.1"/> 
        </geometry>
        <material name="red">
            <color rgba="1.0 0.0 0.0 1.0"/>
            <texture filename=""/>
        </material>
    </visual>
    <collision>
        <origin xyz="0.0 0.0 0.0" rpy="0.0 0.0 0.0"/>
        <geometry>
            <cylinder radius="0.15" length="0.1"/> 
        </geometry>
    </collision>
</link>

<joint name="rear_left_wheel_joint" type="continuous">
    <origin xyz="0.25 -0.4 .0" rpy="1.57 0.0 0.0"/>
    <parent link="custom_base_link"/>
    <child link="rear_left_wheel_link"/>
    <axis xyz="0.0 0.0 1.0"/>
</joint>

<link name="front_right_wheel_link">
    <inertial>
        <origin xyz="0.0 0.0 0.0" rpy="0.0 0.0 0.0"/>
        <mass value="1.0"/>
        <inertia ixx="0.4" ixy="0.0" ixz="0.0"
                 iyy="0.4" iyz="0.0"
                 izz="0.2"/>
    </inertial>
    <visual name="">
        <origin xyz="0.0 0.0 0.0" rpy="0.0 0.0 0.0"/>
        <geometry>
            <cylinder radius="0.15" length="0.1"/> 
        </geometry>
        <material name="red">
            <color rgba="1.0 0.0 0.0 1.0"/>
            <texture filename=""/>
        </material>
    </visual>
    <collision>
        <origin xyz="0.0 0.0 0.0" rpy="0.0 0.0 0.0"/>
        <geometry>
            <cylinder radius="0.15" length="0.1"/> 
        </geometry>
    </collision>
</link>

<joint name="front_right_wheel_joint" type="continuous">
    <origin xyz="-0.25 0.4 .0" rpy="1.57 0.0 0.0"/>
    <parent link="custom_base_link"/>
    <child link="front_right_wheel_link"/>
    <axis xyz="0.0 0.0 1.0"/>
</joint>

<link name="front_left_wheel_link">
    <inertial>
        <origin xyz="0.0 0.0 0.0" rpy="0.0 0.0 0.0"/>
        <mass value="1.0"/>
        <inertia ixx="0.4" ixy="0.0" ixz="0.0"
                 iyy="0.4" iyz="0.0"
                 izz="0.2"/>
    </inertial>
    <visual name="">
        <origin xyz="0.0 0.0 0.0" rpy="0.0 0.0 0.0"/>
        <geometry>
            <cylinder radius="0.15" length="0.1"/> 
        </geometry>
        <material name="red">
            <color rgba="1.0 0.0 0.0 1.0"/>
            <texture filename=""/>
        </material>
    </visual>
    <collision>
        <origin xyz="0.0 0.0 0.0" rpy="0.0 0.0 0.0"/>
        <geometry>
            <cylinder radius="0.15" length="0.1"/> 
        </geometry>
    </collision>
</link>

<joint name="front_left_wheel_joint" type="continuous">
    <origin xyz="-0.25 -0.4 .0" rpy="1.57 0.0 0.0"/>
    <parent link="custom_base_link"/>
    <child link="front_left_wheel_link"/>
    <axis xyz="0.0 0.0 1.0"/>
</joint>

</robot>